Traceback (most recent call last):
  File "/home/facjaramillo/anaconda3/lib/python3.9/site-packages/jupyter_cache/executors/utils.py", line 58, in single_nb_execution
    executenb(
  File "/home/facjaramillo/anaconda3/lib/python3.9/site-packages/nbclient/client.py", line 1204, in execute
    return NotebookClient(nb=nb, resources=resources, km=km, **kwargs).execute()
  File "/home/facjaramillo/anaconda3/lib/python3.9/site-packages/nbclient/util.py", line 84, in wrapped
    return just_run(coro(*args, **kwargs))
  File "/home/facjaramillo/anaconda3/lib/python3.9/site-packages/nbclient/util.py", line 62, in just_run
    return loop.run_until_complete(coro)
  File "/home/facjaramillo/anaconda3/lib/python3.9/asyncio/base_events.py", line 647, in run_until_complete
    return future.result()
  File "/home/facjaramillo/anaconda3/lib/python3.9/site-packages/nbclient/client.py", line 663, in async_execute
    await self.async_execute_cell(
  File "/home/facjaramillo/anaconda3/lib/python3.9/site-packages/nbclient/client.py", line 965, in async_execute_cell
    await self._check_raise_for_error(cell, cell_index, exec_reply)
  File "/home/facjaramillo/anaconda3/lib/python3.9/site-packages/nbclient/client.py", line 862, in _check_raise_for_error
    raise CellExecutionError.from_cell_and_msg(cell, exec_reply_content)
nbclient.exceptions.CellExecutionError: An error occurred while executing the following cell:
------------------
import numpy as np

archivo = np.genfromtxt("/content/trayectorias_t100.txt")

archivo.ndim
------------------

[0;31m---------------------------------------------------------------------------[0m
[0;31mOSError[0m                                   Traceback (most recent call last)
Input [0;32mIn [1][0m, in [0;36m<cell line: 3>[0;34m()[0m
[1;32m      1[0m [38;5;28;01mimport[39;00m [38;5;21;01mnumpy[39;00m [38;5;28;01mas[39;00m [38;5;21;01mnp[39;00m
[0;32m----> 3[0m archivo [38;5;241m=[39m [43mnp[49m[38;5;241;43m.[39;49m[43mgenfromtxt[49m[43m([49m[38;5;124;43m"[39;49m[38;5;124;43m/content/trayectorias_t100.txt[39;49m[38;5;124;43m"[39;49m[43m)[49m
[1;32m      5[0m archivo[38;5;241m.[39mndim

File [0;32m~/anaconda3/lib/python3.9/site-packages/numpy/lib/npyio.py:1793[0m, in [0;36mgenfromtxt[0;34m(fname, dtype, comments, delimiter, skip_header, skip_footer, converters, missing_values, filling_values, usecols, names, excludelist, deletechars, replace_space, autostrip, case_sensitive, defaultfmt, unpack, usemask, loose, invalid_raise, max_rows, encoding, like)[0m
[1;32m   1791[0m     fname [38;5;241m=[39m os_fspath(fname)
[1;32m   1792[0m [38;5;28;01mif[39;00m [38;5;28misinstance[39m(fname, [38;5;28mstr[39m):
[0;32m-> 1793[0m     fid [38;5;241m=[39m [43mnp[49m[38;5;241;43m.[39;49m[43mlib[49m[38;5;241;43m.[39;49m[43m_datasource[49m[38;5;241;43m.[39;49m[43mopen[49m[43m([49m[43mfname[49m[43m,[49m[43m [49m[38;5;124;43m'[39;49m[38;5;124;43mrt[39;49m[38;5;124;43m'[39;49m[43m,[49m[43m [49m[43mencoding[49m[38;5;241;43m=[39;49m[43mencoding[49m[43m)[49m
[1;32m   1794[0m     fid_ctx [38;5;241m=[39m contextlib[38;5;241m.[39mclosing(fid)
[1;32m   1795[0m [38;5;28;01melse[39;00m:

File [0;32m~/anaconda3/lib/python3.9/site-packages/numpy/lib/_datasource.py:193[0m, in [0;36mopen[0;34m(path, mode, destpath, encoding, newline)[0m
[1;32m    156[0m [38;5;250m[39m[38;5;124;03m"""[39;00m
[1;32m    157[0m [38;5;124;03mOpen `path` with `mode` and return the file object.[39;00m
[1;32m    158[0m 
[0;32m   (...)[0m
[1;32m    189[0m 
[1;32m    190[0m [38;5;124;03m"""[39;00m
[1;32m    192[0m ds [38;5;241m=[39m DataSource(destpath)
[0;32m--> 193[0m [38;5;28;01mreturn[39;00m [43mds[49m[38;5;241;43m.[39;49m[43mopen[49m[43m([49m[43mpath[49m[43m,[49m[43m [49m[43mmode[49m[43m,[49m[43m [49m[43mencoding[49m[38;5;241;43m=[39;49m[43mencoding[49m[43m,[49m[43m [49m[43mnewline[49m[38;5;241;43m=[39;49m[43mnewline[49m[43m)[49m

File [0;32m~/anaconda3/lib/python3.9/site-packages/numpy/lib/_datasource.py:533[0m, in [0;36mDataSource.open[0;34m(self, path, mode, encoding, newline)[0m
[1;32m    530[0m     [38;5;28;01mreturn[39;00m _file_openers[ext](found, mode[38;5;241m=[39mmode,
[1;32m    531[0m                               encoding[38;5;241m=[39mencoding, newline[38;5;241m=[39mnewline)
[1;32m    532[0m [38;5;28;01melse[39;00m:
[0;32m--> 533[0m     [38;5;28;01mraise[39;00m [38;5;167;01mIOError[39;00m([38;5;124m"[39m[38;5;132;01m%s[39;00m[38;5;124m not found.[39m[38;5;124m"[39m [38;5;241m%[39m path)

[0;31mOSError[0m: /content/trayectorias_t100.txt not found.
OSError: /content/trayectorias_t100.txt not found.

